(mydashenv) mitun$python3 dash_script_new.py
 * Serving Flask app "dash" (lazy loading)
 * Environment: production
   WARNING: This is a development server. Do not use it in a production deployment.
   Use a production WSGI server instead.
 * Debug mode: off
 * Running on http://0.0.0.0:8300/ (Press CTRL+C to quit)
127.0.0.1 - - [10/Jan/2020 15:09:38] "GET / HTTP/1.1" 200 -
127.0.0.1 - - [10/Jan/2020 15:09:39] "GET /_dash-dependencies HTTP/1.1" 200 -
127.0.0.1 - - [10/Jan/2020 15:09:39] "GET /_dash-layout HTTP/1.1" 200 -
[2020-01-10 15:09:39,674] ERROR in app: Exception on /_dash-update-component [POST]

Traceback (most recent call last):
  File "/anaconda3/envs/mydashenv/lib/python3.6/site-packages/flask/app.py", line 2446, in wsgi_app
    response = self.full_dispatch_request()
  File "/anaconda3/envs/mydashenv/lib/python3.6/site-packages/flask/app.py", line 1951, in full_dispatch_request
    rv = self.handle_user_exception(e)
  File "/anaconda3/envs/mydashenv/lib/python3.6/site-packages/flask/app.py", line 1820, in handle_user_exception
    reraise(exc_type, exc_value, tb)
  File "/anaconda3/envs/mydashenv/lib/python3.6/site-packages/flask/_compat.py", line 39, in reraise
    raise value
  File "/anaconda3/envs/mydashenv/lib/python3.6/site-packages/flask/app.py", line 1949, in full_dispatch_request
    rv = self.dispatch_request()
  File "/anaconda3/envs/mydashenv/lib/python3.6/site-packages/flask/app.py", line 1935, in dispatch_request
    return self.view_functions[rule.endpoint](**req.view_args)
  File "/anaconda3/envs/mydashenv/lib/python3.6/site-packages/dash/dash.py", line 556, in dispatch
    return self.callback_map[target_id]['callback'](*args)
  File "/anaconda3/envs/mydashenv/lib/python3.6/site-packages/dash/dash.py", line 524, in add_context
    cls=plotly.utils.PlotlyJSONEncoder),
  File "/anaconda3/envs/mydashenv/lib/python3.6/json/__init__.py", line 238, in dumps
    **kw).encode(obj)
  File "/anaconda3/envs/mydashenv/lib/python3.6/site-packages/plotly/utils.py", line 136, in encode
    encoded_o = super(PlotlyJSONEncoder, self).encode(o)
  File "/anaconda3/envs/mydashenv/lib/python3.6/json/encoder.py", line 199, in encode
    chunks = self.iterencode(o, _one_shot=True)
  File "/anaconda3/envs/mydashenv/lib/python3.6/json/encoder.py", line 257, in iterencode
    return _iterencode(o, 0)
  File "/anaconda3/envs/mydashenv/lib/python3.6/site-packages/plotly/utils.py", line 204, in default
    return _json.JSONEncoder.default(self, obj)
  File "/anaconda3/envs/mydashenv/lib/python3.6/json/encoder.py", line 180, in default
    o.__class__.__name__)
TypeError: Object of type 'generator' is not JSON serializable
127.0.0.1 - - [10/Jan/2020 15:09:39] "POST /_dash-update-component HTTP/1.1" 500 -
127.0.0.1 - - [10/Jan/2020 15:09:39] "GET /favicon.ico HTTP/1.1" 200 -
